C = 0, N = 24, L = 40, p = 0.03
Traceback (most recent call last):
  File "/Users/dayeon/data/git/optimizing-qLDPC-code/optimization/random_walk.py", line 55, in <module>
    with h5py.File(input_file, 'r') as f:
         ^^^^^^^^^^^^^^^^^^^^^^^^^^
  File "/Users/dayeon/Library/Python/3.12/lib/python/site-packages/h5py/_hl/files.py", line 564, in __init__
    fid = make_fid(name, mode, userblock_size, fapl, fcpl, swmr=swmr)
          ^^^^^^^^^^^^^^^^^^^^^^^^^^^^^^^^^^^^^^^^^^^^^^^^^^^^^^^^^^^
  File "/Users/dayeon/Library/Python/3.12/lib/python/site-packages/h5py/_hl/files.py", line 238, in make_fid
    fid = h5f.open(name, flags, fapl=fapl)
          ^^^^^^^^^^^^^^^^^^^^^^^^^^^^^^^^
  File "h5py/_objects.pyx", line 54, in h5py._objects.with_phil.wrapper
  File "h5py/_objects.pyx", line 55, in h5py._objects.with_phil.wrapper
  File "h5py/h5f.pyx", line 102, in h5py.h5f.open
FileNotFoundError: [Errno 2] Unable to synchronously open file (unable to open file: name = 'optimization/results/random_walk_with_distance.hdf5', errno = 2, error message = 'No such file or directory', flags = 0, o_flags = 0)
